Workbook
Name BaseFloor: Settings!$B$14
Name K_league: Settings!$B$10
Name Lambda: Settings!$B$11
Name MinGP_base: Settings!$B$5
Name MinGP_curve: Settings!$B$6
Name RatioCap: Settings!$B$13
Name RatioFloor: Settings!$B$12
Name W_older: Settings!$B$8
Name W_recent: Settings!$B$7
Name Yardstick: Settings!$B$9

Sheet Read me
A1: Aging curve walkthrough: three traded forwards
A3: What this is | B3: The production aging curve worked through with real data for three forwards, each valued on the day he was traded. Every number is either copied from the source data (blue) or computed by an Excel formula you can inspect (black). Change a setting on the Settings sheet and everything updates.
A4: Built by | B4: valuation_walkthrough.py v1.0 (2026-09-25). Its hand arithmetic was checked against the production code (aging_curve.py, skater_forward_projection.py) before this file was written, and this file's formula results were checked against it after recalculation.
A5: Players | B5: Ryan O'Reilly (Buffalo to St. Louis, 2018-07-01, valued as of 2018-19); Nazem Kadri (Toronto to Colorado, 2019-07-01, valued as of 2019-20); Max Pacioretty (Montreal to Vegas, 2018-09-10, valued as of 2018-19)
A6: Sheets, per player | B6: 1 Seasons: his WAR by season and the starting level. 2 Profile: his eight comparison measures. 3 Comparables: every eligible comparable, its distance and weight. 4 Aging path: how the weights become a curve and the curve becomes projected WAR.
A7: Shared sheets | B7: Settings: every constant the formulas use. Yardstick: how the shared yardstick is built and how distance becomes weight.
A8: Colours | B8: Blue text: data copied from source files or from the production code. Black: formulas. Green: links to another sheet. Yellow fill: key results and settings. Grey rows: seasons after the valuation date, shown for hindsight only.
A9: WAR | B9: Wins above replacement from Patrick Bacon's public model. A season total unless a column says 'per 82 games' (WAR / games x 82).
A10: Not included | B10: Dollars, cap hits, exit probabilities and discounting. This file covers the aging curve only.

Sheet Settings
A1: Model settings used in every calculation
A2: Blue numbers are copied from the production code (20_CODE/aging_curve.py and skater_forward_projection.py) or computed by it. Every formula elsewhere points at these cells, so changing one here flows through the whole workbook.
A4: Setting | B4: Value | C4: Where it comes from and what it does
A5: Minimum games for a season to count toward the starting level | B5: 10 | C5: skater_forward_projection.py MIN_GP. A season with fewer games is ignored for the starting level.
A6: Minimum games for a season to count in the aging model | B6: 20 | C6: aging_curve.py MIN_GP. Applies to the player's own profile seasons and to every comparable.
A7: Starting level: weight on last season | B7: 0.6 | C7: skater_forward_projection.py W_T1.
A8: Starting level: weight on the season before | B8: 0.4 | C8: skater_forward_projection.py W_T2.
A9: Yardstick (median profile distance) | B9: 2.5264128 | C9: AgingModel.h, recomputed on the Yardstick sheet. One number for every player, both positions, all ages.
A10: Weight given to the league average (in comparable-weight units) | B10: 10 | C10: aging_curve.py SHRINK_K. Every 'players like him' average is blended with the league average for his position and age as if the league average were one more comparable carrying this much weight.
A11: Share of the starting curve level kept from his own production | B11: 0.55 | C11: aging_curve.py LAMBDA. The rest (1 - Lambda) comes from the 'players like him' level.
A12: Lowest multiplier allowed | B12: 0 | C12: skater_forward_projection.py RATIO_FLOOR: a projection can fall to replacement level, not below.
A13: Highest multiplier allowed | B13: 3 | C13: skater_forward_projection.py RATIO_CAP.
A14: Curve level at or below which multipliers are not used | B14: 0.25 | C14: skater_forward_projection.py CURVE_BASE_FLOOR: dividing by a curve level this close to zero is unstable, so the projection holds flat instead.
A16: The eight profile measures (forwards)
A17: Measure | B17: Weight | C17: How it is built / plain meaning | D17: Forward average | E17: Forward standard deviation
A18: Even-strength offence share | B18: 0.2 | C18: his even-strength offence WAR as a share of his total style WAR | D18: 0.19232245 | E18: 0.27941252
A19: Even-strength defence share | B19: 0.2 | C19: his even-strength defence WAR as a share of his total style WAR | D19: -0.0066418964 | E19: 0.24003106
A20: Power-play share | B20: 0.2 | C20: his power-play WAR as a share of his total style WAR | D20: 0.053127196 | E20: 0.11037293
A21: Penalty-kill share | B21: 0.2 | C21: his penalty-kill WAR as a share of his total style WAR | D21: -0.0029444758 | E21: 0.081318614
A22: Shooting share | B22: 0.2 | C22: his shooting WAR as a share of his total style WAR | D22: 0.24786123 | E22: 0.37167162
A23: Ice time per game (min) | B23: 1 | C23: total minutes over the window divided by total games | D23: 15.255212 | E23: 2.8795457
A24: Production level (WAR per 82) | B24: 1 | C24: simple average of the two seasons' WAR per 82 games | D24: 1.3082679 | E24: 1.4464355
A25: Production trend (WAR per 82, per year) | B25: 1 | C25: later season's WAR per 82 minus the earlier season's | D25: -0.053335801 | E25: 1.482775
A26: Total weight | B26: =SUM(B18:B25) -> 4
A27: Weights are the production values: each of the four groups (style, ice time, level, trend) carries 1.0, and the five style shares split theirs, 0.2 each. As fractions of the total (4.0) that is 1/20 per style share and 1/4 for each of the other three. Scaling every weight by the same number would scale every distance AND the yardstick together, leaving every comparable's weight unchanged. The forward average and standard deviation are taken over every forward profile in the comparable pool, all ages together (AgingModel.stats). Penalty WAR is left out of the style shares (it made the shares add to a fixed total, so one of them carried no new information).

Sheet Yardstick
A1: The yardstick: one shared scale for 'near' and 'far'
A2: How production builds it (AgingModel._build_bank): take every profile in the comparable pool, separately for forwards and defencemen. Draw up to 1,200 profiles per position at random (seed 0). These are profiles of ALL ages mixed together, not just players of one age. Measure the distance between every pair of sampled forwards and every pair of sampled defencemen (never a forward against a defenceman). Pool the two lists of distances and take the middle value (the median). That median is the yardstick: one number used for every player at every age.
B4: Forwards | C4: Defence | D4: Pooled
A5: Profiles in the pool | B5: 4950 | C5: 2581
A6: Profiles sampled | B6: 1200 | C6: 1200
A7: Pairs measured | B7: 719400 | C7: 719400 | D7: =B7+C7 -> 1438800
A8: Median distance within the group | B8: 2.4851603 | C8: 2.5650631 | D8: =Yardstick -> 2.5264128
A10: Spread of the pooled distances
A11: Percentile | B11: Distance | C11: In yardsticks
A12: 10th percentile | B12: 1.5398154 | C12: =B12/Yardstick -> 0.60948685
A13: 25th percentile | B13: 1.9703446 | C13: =B13/Yardstick -> 0.77989813
A14: 50th percentile | B14: 2.5264128 | C14: =B14/Yardstick -> 1
A15: 75th percentile | B15: 3.1986312 | C15: =B15/Yardstick -> 1.2660762
A16: 90th percentile | B16: 3.9078213 | C16: =B16/Yardstick -> 1.5467865
A18: From distance to weight
A19: weight = EXP( -(distance^2) / (2 x yardstick^2) ). An exact match gets weight 1. A comparable exactly one yardstick away gets EXP(-0.5) = 0.607, which is where the 0.61 comes from: it is a weight, not a distance. Two yardsticks away gets EXP(-2) = 0.135. The fall-off speeds up with distance (it is the bell-curve shape), so far-away profiles count for almost nothing.
A21: Distance, in yardsticks | B21: Distance | C21: Weight
A22: 0 | B22: =A22*Yardstick -> 0 | C22: =EXP(-(B22^2)/(2*Yardstick^2)) -> 1
A23: 0.25 | B23: =A23*Yardstick -> 0.63160321 | C23: =EXP(-(B23^2)/(2*Yardstick^2)) -> 0.96923323
A24: 0.5 | B24: =A24*Yardstick -> 1.2632064 | C24: =EXP(-(B24^2)/(2*Yardstick^2)) -> 0.8824969
A25: 0.75 | B25: =A25*Yardstick -> 1.8948096 | C25: =EXP(-(B25^2)/(2*Yardstick^2)) -> 0.7548396
A26: 1 | B26: =A26*Yardstick -> 2.5264128 | C26: =EXP(-(B26^2)/(2*Yardstick^2)) -> 0.60653066
A27: 1.25 | B27: =A27*Yardstick -> 3.158016 | C27: =EXP(-(B27^2)/(2*Yardstick^2)) -> 0.45783336
A28: 1.5 | B28: =A28*Yardstick -> 3.7896192 | C28: =EXP(-(B28^2)/(2*Yardstick^2)) -> 0.32465247
A29: 2 | B29: =A29*Yardstick -> 5.0528257 | C29: =EXP(-(B29^2)/(2*Yardstick^2)) -> 0.13533528
A30: 2.5 | B30: =A30*Yardstick -> 6.3160321 | C30: =EXP(-(B30^2)/(2*Yardstick^2)) -> 0.043936934
A31: 3 | B31: =A31*Yardstick -> 7.5792385 | C31: =EXP(-(B31^2)/(2*Yardstick^2)) -> 0.011108997
A33: For comparison only: a yardstick built from one age and position
A34: Production does NOT do this. These are the medians you would get using only forwards of each walkthrough player's comparison age (every pair, no sampling). Listed so the shared yardstick can be compared with an age-specific one.
A36: Player: forwards of age | B36: Profiles | C36: Median distance | D36: In shared yardsticks
A37: Ryan O'Reilly: forwards aged 26 | B37: 472 | C37: 2.5559835 | D37: =C37/Yardstick -> 1.0117046
A38: Nazem Kadri: forwards aged 28 | B38: 400 | C38: 2.5542229 | D38: =C38/Yardstick -> 1.0110077
A39: Max Pacioretty: forwards aged 29 | B39: 354 | C39: 2.5858027 | D39: =C39/Yardstick -> 1.0235076

Sheet OReilly 1 Seasons
A1: Ryan O'Reilly: every season of WAR
A2: Traded Buffalo to St. Louis on 2018-07-01. The model values him as of the 2018-19 season, so it may use seasons up to 2017-18 only. Grey rows are later seasons, shown for hindsight and never used by the model. Source: Patrick Bacon's WAR export (10_SOURCE/WAR.csv); a season split between two teams is added together into one row.
A4: Season | B4: Team | C4: Age | D4: Games | E4: Ice time (min) | F4: Even-strength offence WAR | G4: Even-strength defence WAR | H4: Power-play WAR | I4: Penalty-kill WAR | J4: Penalties WAR | K4: Shooting WAR | L4: Total WAR | M4: Season-length factor | N4: WAR, season-length adjusted | O4: WAR per 82 games | P4: Used by the model for
A5: 2009-10 | B5: COL | C5: 18 | D5: 81 | E5: 1341.1667 | F5: 0.050008396 | G5: -0.30096042 | H5: -0.047970962 | I5: -0.30259977 | J5: 0.31528571 | K5: -0.032233278 | L5: -0.31847032 | M5: 1 | N5: =L5*M5 -> -0.31847032 | O5: =L5/D5*82 -> -0.32240206
A6: 2010-11 | B6: COL | C6: 19 | D6: 74 | E6: 1165.25 | F6: 0.2748809 | G6: 0.028877659 | H6: -0.0099528967 | I6: -0.15914257 | J6: 0.2753381 | K6: 0.82187542 | L6: 1.2318766 | M6: 1 | N6: =L6*M6 -> 1.2318766 | O6: =L6/D6*82 -> 1.3650525
A7: 2011-12 | B7: COL | C7: 20 | D7: 81 | E7: 1538.1667 | F7: 0.63208416 | G7: 0.63810737 | H7: 0.03150421 | I7: 0.06682396 | J7: 0.41556456 | K7: 0.75676926 | L7: 2.5408535 | M7: 1 | N7: =L7*M7 -> 2.5408535 | O7: =L7/D7*82 -> 2.5722221
A8: 2012-13 | B8: COL | C8: 21 | D8: 29 | E8: 521.91667 | F8: 0.17364263 | G8: 0.19599955 | H8: 0.10578858 | I8: 0.0070170751 | J8: 0.21894985 | K8: 0.40497107 | L8: 1.1063688 | M8: 1 | N8: =L8*M8 -> 1.1063688 | O8: =L8/D8*82 -> 3.1283531
A9: 2013-14 | B9: COL | C9: 22 | D9: 80 | E9: 1540.25 | F9: 0.56618149 | G9: -0.24315999 | H9: 0.44107604 | I9: 0.14174333 | J9: 0.65239323 | K9: 2.3437549 | L9: 3.901989 | M9: 1 | N9: =L9*M9 -> 3.901989 | O9: =L9/D9*82 -> 3.9995388
A10: 2014-15 | B10: COL | C10: 23 | D10: 82 | E10: 1542.25 | F10: 0.39657853 | G10: 0.36431636 | H10: 0.35490069 | I10: -0.052496074 | J10: 0.38220266 | K10: 0.3170187 | L10: 1.7625209 | M10: 1 | N10: =L10*M10 -> 1.7625209 | O10: =L10/D10*82 -> 1.7625209
A11: 2015-16 | B11: BUF | C11: 24 | D11: 71 | E11: 1480.1167 | F11: 0.42734664 | G11: -0.27875102 | H11: 0.94390371 | I11: 0.043422697 | J11: 0.4658086 | K11: 1.4515532 | L11: 3.0532838 | M11: 1 | N11: =L11*M11 -> 3.0532838 | O11: =L11/D11*82 -> 3.5263278
A12: 2016-17 | B12: BUF | C12: 25 | D12: 72 | E12: 1488.55 | F12: 0.56602406 | G12: 0.17154919 | H12: 0.73740933 | I12: -0.22762153 | J12: 0.87936305 | K12: 1.1022063 | L12: 3.2289304 | M12: 1 | N12: =L12*M12 -> 3.2289304 | O12: =L12/D12*82 -> 3.6773929 | P12: starting level (if 10+ games); comparison profile at age 25
A13: 2017-18 | B13: BUF | C13: 26 | D13: 81 | E13: 1606.7333 | F13: 0.63118387 | G13: 0.49498323 | H13: 1.0273105 | I13: -0.19707335 | J13: 0.68316725 | K13: 0.67381113 | L13: 3.3133826 | M13: 1 | N13: =L13*M13 -> 3.3133826 | O13: =L13/D13*82 -> 3.3542886 | P13: starting level (if 10+ games); comparison profile at age 26
A14: 2018-19 | B14: STL | C14: 27 | D14: 82 | E14: 1630.3833 | F14: 1.0202456 | G14: 0.55498014 | H14: 0.64736343 | I14: 0.042690755 | J14: 0.69429213 | K14: 0.98492593 | L14: 3.944498 | M14: 1 | N14: =L14*M14 -> 3.944498 | O14: =L14/D14*82 -> 3.944498 | P14: hindsight only
A15: 2019-20 | B15: STL | C15: 28 | D15: 71 | E15: 1403.2667 | F15: 0.82001771 | G15: 0.70883071 | H15: 0.3631603 | I15: -0.14366879 | J15: 0.26801753 | K15: -0.16512079 | L15: 1.8512367 | M15: 1.1714286 | N15: =L15*M15 -> 2.1685915 | O15: =L15/D15*82 -> 2.138048 | P15: hindsight only
A16: 2020-21 | B16: STL | C16: 29 | D16: 56 | E16: 1098.8167 | F16: 0.41705311 | G16: 0.17641002 | H16: 0.23858789 | I16: -0.28970667 | J16: 0.039056428 | K16: 1.9086624 | L16: 2.4900631 | M16: 1.4642857 | N16: =L16*M16 -> 3.6461639 | O16: =L16/D16*82 -> 3.6461639 | P16: hindsight only
A17: 2021-22 | B17: STL | C17: 30 | D17: 78 | E17: 1424.6 | F17: -0.059689024 | G17: 0.67677893 | H17: 0.55605068 | I17: -0.10534502 | J17: 0.76340378 | K17: 0.38676175 | L17: 2.2179611 | M17: 1 | N17: =L17*M17 -> 2.2179611 | O17: =L17/D17*82 -> 2.3317027 | P17: hindsight only
A18: 2022-23 | B18: STL/TOR | C18: 31 | D18: 53 | E18: 924.4 | F18: 0.89572481 | G18: 0.1636061 | H18: -0.075736027 | I18: -0.066168608 | J18: 0.032856946 | K18: 0.74704568 | L18: 1.6973289 | M18: 1 | N18: =L18*M18 -> 1.6973289 | O18: =L18/D18*82 -> 2.626056 | P18: hindsight only
A19: 2023-24 | B19: NSH | C19: 32 | D19: 82 | E19: 1553.7333 | F19: 1.0171166 | G19: 0.30146336 | H19: 0.22524603 | I19: 0.14129415 | J19: 0.19356352 | K19: 1.1033694 | L19: 3.0624426 | M19: 1 | N19: =L19*M19 -> 3.0624426 | O19: =L19/D19*82 -> 3.0624426 | P19: hindsight only
A20: 2024-25 | B20: NSH | C20: 33 | D20: 79 | E20: 1428.35 | F20: 0.56887549 | G20: 0.30937604 | H20: 0.35879725 | I20: -0.026653396 | J20: 0.19702474 | K20: 0.16775271 | L20: 1.5805724 | M20: 1 | N20: =L20*M20 -> 1.5805724 | O20: =L20/D20*82 -> 1.6405942 | P20: hindsight only
A21: 2025-26 | B21: NSH | C21: 34 | D21: 81 | E21: 1586.2 | F21: 0.53158823 | G21: 0.11185785 | H21: 0.48642487 | I21: -0.0057367626 | J21: 0.055873471 | K21: 1.0056776 | L21: 2.2368885 | M21: 1 | N21: =L21*M21 -> 2.2368885 | O21: =L21/D21*82 -> 2.2645044 | P21: hindsight only
A23: Starting level: how good is he now?
A24: 60% of last season's WAR plus 40% of the season before, each counted only if he played at least the minimum games. If only one season counts, it supplies the whole starting level. This is a season total (not a per-82 rate); it is the number the aging curve's multipliers are applied to on the Aging path sheet.
B26: Season | C26: Games | D26: Adjusted WAR | E26: Counts? | F26: Weight
A27: Last season | B27: =A13 -> 2017-18 | C27: =D13 -> 81 | D27: =N13 -> 3.3133826 | E27: =C27>=MinGP_base -> TRUE | F27: =W_recent -> 0.6
A28: Season before | B28: =A12 -> 2016-17 | C28: =D12 -> 72 | D28: =N12 -> 3.2289304 | E28: =C28>=MinGP_base -> TRUE | F28: =W_older -> 0.4
A30: Starting level (WAR) | D30: =IF(AND(E27,E28),F27*D27+F28*D28,IF(E27,D27,IF(E28,D28,NA()))) -> 3.2796017

Sheet OReilly 2 Profile
A1: Ryan O'Reilly: his comparison profile
A2: He is 27 in the valuation season (2018-19). The comparison is made one season earlier, at age 26, so it rests only on completed seasons (2017-18 and before). His profile at age 26 uses his two consecutive seasons at ages 25 and 26, each with at least 20 games. It is then compared with every other forward's profile at age 26.
A4: Profile season | B4: Age | C4: Games | D4: Ice time (min) | E4: EV offence WAR | F4: EV defence WAR | G4: Power-play WAR | H4: Penalty-kill WAR | I4: Shooting WAR | J4: Total WAR | K4: WAR per 82
A5: ='OReilly 1 Seasons'!$A$12 -> 2016-17 | B5: ='OReilly 1 Seasons'!$C$12 -> 25 | C5: ='OReilly 1 Seasons'!$D$12 -> 72 | D5: ='OReilly 1 Seasons'!$E$12 -> 1488.55 | E5: ='OReilly 1 Seasons'!$F$12 -> 0.56602406 | F5: ='OReilly 1 Seasons'!$G$12 -> 0.17154919 | G5: ='OReilly 1 Seasons'!$H$12 -> 0.73740933 | H5: ='OReilly 1 Seasons'!$I$12 -> -0.22762153 | I5: ='OReilly 1 Seasons'!$K$12 -> 1.1022063 | J5: ='OReilly 1 Seasons'!$L$12 -> 3.2289304 | K5: ='OReilly 1 Seasons'!$O$12 -> 3.6773929
A6: ='OReilly 1 Seasons'!$A$13 -> 2017-18 | B6: ='OReilly 1 Seasons'!$C$13 -> 26 | C6: ='OReilly 1 Seasons'!$D$13 -> 81 | D6: ='OReilly 1 Seasons'!$E$13 -> 1606.7333 | E6: ='OReilly 1 Seasons'!$F$13 -> 0.63118387 | F6: ='OReilly 1 Seasons'!$G$13 -> 0.49498323 | G6: ='OReilly 1 Seasons'!$H$13 -> 1.0273105 | H6: ='OReilly 1 Seasons'!$I$13 -> -0.19707335 | I6: ='OReilly 1 Seasons'!$K$13 -> 0.67381113 | J6: ='OReilly 1 Seasons'!$L$13 -> 3.3133826 | K6: ='OReilly 1 Seasons'!$O$13 -> 3.3542886
A8: Style shares: each style WAR summed over the two seasons, divided by the sum of the five style WARs ignoring their signs (Penalties WAR is left out). They describe the MIX of his game, not its size. Standard score = (value - forward average) / forward standard deviation. Weighted score = standard score x square root of the measure weight.
A9: Measure | D9: His value | E9: Forward average | F9: Forward SD | G9: Standard score | H9: Measure weight | I9: Weighted score
A10: Even-strength offence share | D10: =SUM(E5:E6)/(ABS(SUM(E5:E6))+ABS(SUM(F5:F6))+ABS(SUM(G5:G6))+ABS(SUM(H5:H6))+ABS(SUM(I5:I6))) -> 0.20538214 | E10: =Settings!$D$18 -> 0.19232245 | F10: =Settings!$E$18 -> 0.27941252 | G10: =(D10-E10)/F10 -> 0.046739823 | H10: =Settings!$B$18 -> 0.2 | I10: =G10*SQRT(H10) -> 0.020902684
A11: Even-strength defence share | D11: =SUM(F5:F6)/(ABS(SUM(E5:E6))+ABS(SUM(F5:F6))+ABS(SUM(G5:G6))+ABS(SUM(H5:H6))+ABS(SUM(I5:I6))) -> 0.11434426 | E11: =Settings!$D$19 -> -0.0066418964 | F11: =Settings!$E$19 -> 0.24003106 | G11: =(D11-E11)/F11 -> 0.50404375 | H11: =Settings!$B$19 -> 0.2 | I11: =G11*SQRT(H11) -> 0.22541522
A12: Power-play share | D12: =SUM(G5:G6)/(ABS(SUM(E5:E6))+ABS(SUM(F5:F6))+ABS(SUM(G5:G6))+ABS(SUM(H5:H6))+ABS(SUM(I5:I6))) -> 0.30273934 | E12: =Settings!$D$20 -> 0.053127196 | F12: =Settings!$E$20 -> 0.11037293 | G12: =(D12-E12)/F12 -> 2.261534 | H12: =Settings!$B$20 -> 0.2 | I12: =G12*SQRT(H12) -> 1.0113888
A13: Penalty-kill share | D13: =SUM(H5:H6)/(ABS(SUM(E5:E6))+ABS(SUM(F5:F6))+ABS(SUM(G5:G6))+ABS(SUM(H5:H6))+ABS(SUM(I5:I6))) -> -0.072856805 | E13: =Settings!$D$21 -> -0.0029444758 | F13: =Settings!$E$21 -> 0.081318614 | G13: =(D13-E13)/F13 -> -0.85973342 | H13: =Settings!$B$21 -> 0.2 | I13: =G13*SQRT(H13) -> -0.38448447
A14: Shooting share | D14: =SUM(I5:I6)/(ABS(SUM(E5:E6))+ABS(SUM(F5:F6))+ABS(SUM(G5:G6))+ABS(SUM(H5:H6))+ABS(SUM(I5:I6))) -> 0.30467745 | E14: =Settings!$D$22 -> 0.24786123 | F14: =Settings!$E$22 -> 0.37167162 | G14: =(D14-E14)/F14 -> 0.15286671 | H14: =Settings!$B$22 -> 0.2 | I14: =G14*SQRT(H14) -> 0.068364072
A15: Ice time per game (min) | D15: =SUM(D5:D6)/SUM(C5:C6) -> 20.23061 | E15: =Settings!$D$23 -> 15.255212 | F15: =Settings!$E$23 -> 2.8795457 | G15: =(D15-E15)/F15 -> 1.7278414 | H15: =Settings!$B$23 -> 1 | I15: =G15*SQRT(H15) -> 1.7278414
A16: Production level (WAR per 82) | D16: =AVERAGE(K5:K6) -> 3.5158407 | E16: =Settings!$D$24 -> 1.3082679 | F16: =Settings!$E$24 -> 1.4464355 | G16: =(D16-E16)/F16 -> 1.5262158 | H16: =Settings!$B$24 -> 1 | I16: =G16*SQRT(H16) -> 1.5262158
A17: Production trend (WAR per 82, per year) | D17: =(K6-K5)/(B6-B5) -> -0.32310432 | E17: =Settings!$D$25 -> -0.053335801 | F17: =Settings!$E$25 -> 1.482775 | G17: =(D17-E17)/F17 -> -0.1819349 | H17: =Settings!$B$25 -> 1 | I17: =G17*SQRT(H17) -> -0.1819349

Sheet OReilly 3 Comparables
A1: Ryan O'Reilly: every forward profile at age 26, and how close each one is
A2: Every forward with a qualifying two-season profile at age 26 is eligible; there is no fixed number of comparables. Ryan O'Reilly's own career is excluded (1 row). Distance = square root of the sum of the eight distance pieces; each piece = measure weight x (his standard score - comparable's standard score)^2. Weight = EXP(-(distance^2) / (2 x yardstick^2)). Rows are sorted by weight. 'After valuation date' marks profiles or yearly changes from seasons that had not been played by 2018-07-01: production draws its comparables from the full 2007-2025 data, so these later seasons do inform the valuation (a documented look-ahead limitation).
A4: Ryan O'Reilly (the target)
F5: Target standard score: Even-strength offence share | G5: Target standard score: Even-strength defence share | H5: Target standard score: Power-play share | I5: Target standard score: Penalty-kill share | J5: Target standard score: Shooting share | K5: Target standard score: Ice time per game (min) | L5: Target standard score: Production level (WAR per 82) | M5: Target standard score: Production trend (WAR per 82, per year)
F6: ='OReilly 2 Profile'!$G$10 -> 0.046739823 | G6: ='OReilly 2 Profile'!$G$11 -> 0.50404375 | H6: ='OReilly 2 Profile'!$G$12 -> 2.261534 | I6: ='OReilly 2 Profile'!$G$13 -> -0.85973342 | J6: ='OReilly 2 Profile'!$G$14 -> 0.15286671 | K6: ='OReilly 2 Profile'!$G$15 -> 1.7278414 | L6: ='OReilly 2 Profile'!$G$16 -> 1.5262158 | M6: ='OReilly 2 Profile'!$G$17 -> -0.1819349
A7: Sum of comparable weights | E7: =SUM($AF$11:$AF$481) -> 231.62089 | G7: Share of weight on the 5 closest | K7: =SUM($AF$11:$AF$15)/E7 -> 0.020229049
A8: Effective number of comparables | E8: =SUM($AF$11:$AF$481)^2/SUMPRODUCT($AF$11:$AF$481,$AF$11:$AF$481) -> 390.5683 | G8: Share of weight on profiles after valuation date | K8: =SUMPRODUCT($AF$11:$AF$481,$E$11:$E$481)/E7 -> 0.56496803
A10: Rank | B10: Comparable | C10: Profile seasons | D10: Age | E10: After valuation date (1 = yes) | F10: Value: Even-strength offence share | G10: Value: Even-strength defence share | H10: Value: Power-play share | I10: Value: Penalty-kill share | J10: Value: Shooting share | K10: Value: Ice time per game (min) | L10: Value: Production level (WAR per 82) | M10: Value: Production trend (WAR per 82, per year) | N10: Standard score: Even-strength offence share | O10: Standard score: Even-strength defence share | P10: Standard score: Power-play share | Q10: Standard score: Penalty-kill share | R10: Standard score: Shooting share | S10: Standard score: Ice time per game (min) | T10: Standard score: Production level (WAR per 82) | U10: Standard score: Production trend (WAR per 82, per year) | V10: Distance piece: Even-strength offence share | W10: Distance piece: Even-strength defence share | X10: Distance piece: Power-play share | Y10: Distance piece: Penalty-kill share | Z10: Distance piece: Shooting share | AA10: Distance piece: Ice time per game (min) | AB10: Distance piece: Production level (WAR per 82) | AC10: Distance piece: Production trend (WAR per 82, per year) | AD10: Distance | AE10: Distance in yardsticks | AF10: Weight | AG10: Share of total weight | AH10: Change in WAR per 82, age 26 to 27 | AI10: That change after valuation date (1 = yes) | AJ10: Change in WAR per 82, age 27 to 28 | AK10: That change after valuation date (1 = yes) | AL10: Change in WAR per 82, age 28 to 29 | AM10: That change after valuation date (1 = yes) | AN10: Change in WAR per 82, age 29 to 30 | AO10: That change after valuation date (1 = yes) | AP10: Change in WAR per 82, age 30 to 31 | AQ10: That change after valuation date (1 = yes)
A11: 1 | B11: Joe Pavelski | C11: 2009-10 & 2010-11 | D11: 26 | E11: 0 | F11: 0.50772108 | G11: 0.027678589 | H11: 0.29345704 | I11: -0.085191313 | J11: 0.085951979 | K11: 19.148921 | L11: 3.0228633 | M11: 0.050163994 | N11: =(F11-Settings!$D$18)/Settings!$E$18 -> 1.128792 | O11: =(G11-Settings!$D$19)/Settings!$E$19 -> 0.14298352 | P11: =(H11-Settings!$D$20)/Settings!$E$20 -> 2.1774346 | Q11: =(I11-Settings!$D$21)/Settings!$E$21 -> -1.0114146 | R11: =(J11-Settings!$D$22)/Settings!$E$22 -> -0.43562446 | S11: =(K11-Settings!$D$23)/Settings!$E$23 -> 1.3521957 | T11: =(L11-Settings!$D$24)/Settings!$E$24 -> 1.1853936 | U11: =(M11-Settings!$D$25)/Settings!$E$25 -> 0.069801414 | V11: =Settings!$B$18*(N11-F$6)^2 -> 0.2341674 | W11: =Settings!$B$19*(O11-G$6)^2 -> 0.026072899 | X11: =Settings!$B$20*(P11-H$6)^2 -> 0.0014145438 | Y11: =Settings!$B$21*(Q11-I$6)^2 -> 0.004601439 | Z11: =Settings!$B$22*(R11-J$6)^2 -> 0.069264372 | AA11: =Settings!$B$23*(S11-K$6)^2 -> 0.14110974 | AB11: =Settings!$B$24*(T11-L$6)^2 -> 0.1161598 | AC11: =Settings!$B$25*(U11-M$6)^2 -> 0.06337117 | AD11: =SQRT(SUM(V11:AC11)) -> 0.81003788 | AE11: =AD11/Yardstick -> 0.32062768 | AF11: =EXP(-(AD11^2)/(2*Yardstick^2)) -> 0.94989763 | AG11: =AF11/$E$7 -> 0.0041010879 | AH11: 0.33035045 | AI11: 0 | AJ11: 0.25739387 | AK11: 0 | AL11: 1.3086287 | AM11: 0 | AN11: 0.85297009 | AO11: 0 | AP11: -0.99598651 | AQ11: 0
A12: 2 | B12: Loui Eriksson | C12: 2010-11 & 2011-12 | D12: 26 | E12: 0 | F12: 0.10753187 | G12: -0.041372676 | H12: 0.25448458 | I12: 0.040017128 | J12: 0.55659375 | K12: 19.778468 | L12: 3.1195734 | M12: -0.25004317 | N12: =(F12-Settings!$D$18)/Settings!$E$18 -> -0.30346022 | O12: =(G12-Settings!$D$19)/Settings!$E$19 -> -0.14469286 | P12: =(H12-Settings!$D$20)/Settings!$E$20 -> 1.8243366 | Q12: =(I12-Settings!$D$21)/Settings!$E$21 -> 0.52831205 | R12: =(J12-Settings!$D$22)/Settings!$E$22 -> 0.83065937 | S12: =(K12-Settings!$D$23)/Settings!$E$23 -> 1.5708229 | T12: =(L12-Settings!$D$24)/Settings!$E$24 -> 1.2522546 | U12: =(M12-Settings!$D$25)/Settings!$E$25 -> -0.13266164 | V12: =Settings!$B$18*(N12-F$6)^2 -> 0.024528014 | W12: =Settings!$B$19*(O12-G$6)^2 -> 0.084171838 | X12: =Settings!$B$20*(P12-H$6)^2 -> 0.038228312 | Y12: =Settings!$B$21*(Q12-I$6)^2 -> 0.38533404 | Z12: =Settings!$B$22*(R12-J$6)^2 -> 0.091880579 | AA12: =Settings!$B$23*(S12-K$6)^2 -> 0.024654827 | AB12: =Settings!$B$24*(T12-L$6)^2 -> 0.075054787 | AC12: =Settings!$B$25*(U12-M$6)^2 -> 0.0024278534 | AD12: =SQRT(SUM(V12:AC12)) -> 0.85222078 | AE12: =AD12/Yardstick -> 0.33732443 | AF12: =EXP(-(AD12^2)/(2*Yardstick^2)) -> 0.94469431 | AG12: =AF12/$E$7 -> 0.0040786231 | AH12: -0.57804338 | AI12: 0 | AJ12: -0.65431191 | AK12: 0 | AL12: 0.5139469 | AM12: 0 | AN12: 1.7044441 | AO12: 0 | AP12: -0.91910328 | AQ12: 0
A13: 3 | B13: Nick Suzuki | C13: 2024-25 & 2025-26 | D13: 26 | E13: 1 | F13: 0.30839482 | G13: 0.1369975 | H13: 0.16305717 | I13: 0.025209162 | J13: 0.36634134 | K13: 19.522967 | L13: 3.4740979 | M13: -0.95900817 | N13: =(F13-Settings!$D$18)/Settings!$E$18 -> 0.41541578 | O13: =(G13-Settings!$D$19)/Settings!$E$19 -> 0.59842005 | P13: =(H13-Settings!$D$20)/Settings!$E$20 -> 0.99598672 | Q13: =(I13-Settings!$D$21)/Settings!$E$21 -> 0.34621394 | R13: =(J13-Settings!$D$22)/Settings!$E$22 -> 0.31877631 | S13: =(K13-Settings!$D$23)/Settings!$E$23 -> 1.4820935 | T13: =(L13-Settings!$D$24)/Settings!$E$24 -> 1.4973567 | U13: =(M13-Settings!$D$25)/Settings!$E$25 -> -0.61079553 | V13: =Settings!$B$18*(N13-F$6)^2 -> 0.027184392 | W13: =Settings!$B$19*(O13-G$6)^2 -> 0.001781377 | X13: =Settings!$B$20*(P13-H$6)^2 -> 0.320322 | Y13: =Settings!$B$21*(Q13-I$6)^2 -> 0.29086181 | Z13: =Settings!$B$22*(R13-J$6)^2 -> 0.0055051992 | AA13: =Settings!$B$23*(S13-K$6)^2 -> 0.060392069 | AB13: =Settings!$B$24*(T13-L$6)^2 -> 0.00083284877 | AC13: =Settings!$B$25*(U13-M$6)^2 -> 0.18392145 | AD13: =SQRT(SUM(V13:AC13)) -> 0.94382262 | AE13: =AD13/Yardstick -> 0.3735821 | AF13: =EXP(-(AD13^2)/(2*Yardstick^2)) -> 0.9325973 | AG13: =AF13/$E$7 -> 0.0040263954
A14: 4 | B14: Mitch Marner | C14: 2022-23 & 2023-24 | D14: 26 | E14: 1 | F14: 0.12272677 | G14: 0.063112713 | H14: 0.24234025 | I14: -0.005492629 | J14: 0.56632763 | K14: 20.460962 | L14: 4.6096923 | M14: -0.5167408 | N14: =(F14-Settings!$D$18)/Settings!$E$18 -> -0.24907859 | O14: =(G14-Settings!$D$19)/Settings!$E$19 -> 0.29060659 | P14: =(H14-Settings!$D$20)/Settings!$E$20 -> 1.7143067 | Q14: =(I14-Settings!$D$21)/Settings!$E$21 -> -0.031335424 | R14: =(J14-Settings!$D$22)/Settings!$E$22 -> 0.85684885 | S14: =(K14-Settings!$D$23)/Settings!$E$23 -> 1.8078374 | T14: =(L14-Settings!$D$24)/Settings!$E$24 -> 2.2824552 | U14: =(M14-Settings!$D$25)/Settings!$E$25 -> -0.31252549 | V14: =Settings!$B$18*(N14-F$6)^2 -> 0.017501707 | W14: =Settings!$B$19*(O14-G$6)^2 -> 0.0091110843 | X14: =Settings!$B$20*(P14-H$6)^2 -> 0.059891558 | Y14: =Settings!$B$21*(Q14-I$6)^2 -> 0.13724865 | Z14: =Settings!$B$22*(R14-J$6)^2 -> 0.099118171 | AA14: =Settings!$B$23*(S14-K$6)^2 -> 0.0063993493 | AB14: =Settings!$B$24*(T14-L$6)^2 -> 0.57189801 | AC14: =Settings!$B$25*(U14-M$6)^2 -> 0.017053903 | AD14: =SQRT(SUM(V14:AC14)) -> 0.95823923 | AE14: =AD14/Yardstick -> 0.37928846 | AF14: =EXP(-(AD14^2)/(2*Yardstick^2)) -> 0.93059616 | AG14: =AF14/$E$7 -> 0.0040177557 | AH14: -0.48909737 | AI14: 1 | AJ14: -0.3425315 | AK14: 1
A15: 5 | B15: Claude Giroux | C15: 2012-13 & 2013-14 | D15: 26 | E15: 0 | F15: 0.23256167 | G15: -0.18234015 | H15: 0.20313402 | I15: 0.012944155 | J15: 0.36902001 | K15: 20.015897 | L15: 3.5269289 | M15: -1.0698504 | N15: =(F15-Settings!$D$18)/Settings!$E$18 -> 0.14401365 | O15: =(G15-Settings!$D$19)/Settings!$E$19 -> -0.7319813 | P15: =(H15-Settings!$D$20)/Settings!$E$20 -> 1.3590906 | Q15: =(I15-Settings!$D$21)/Settings!$E$21 -> 0.19538738 | R15: =(J15-Settings!$D$22)/Settings!$E$22 -> 0.32598341 | S15: =(K15-Settings!$D$23)/Settings!$E$23 -> 1.6532767 | T15: =(L15-Settings!$D$24)/Settings!$E$24 -> 1.5338817 | U15: =(M15-Settings!$D$25)/Settings!$E$25 -> -0.68554876 | V15: =Settings!$B$18*(N15-F$6)^2 -> 0.0018924395 | W15: =Settings!$B$19*(O15-G$6)^2 -> 0.30555159 | X15: =Settings!$B$20*(P15-H$6)^2 -> 0.16288081 | Y15: =Settings!$B$21*(Q15-I$6)^2 -> 0.22265598 | Z15: =Settings!$B$22*(R15-J$6)^2 -> 0.0059938783 | AA15: =Settings!$B$23*(S15-K$6)^2 -> 0.0055599008 | AB15: =Settings!$B$24*(T15-L$6)^2 -> 5.8765095e-05 | AC15: =Settings!$B$25*(U15-M$6)^2 -> 0.25362693 | AD15: =SQRT(SUM(V15:AC15)) -> 0.97888727 | AE15: =AD15/Yardstick -> 0.38746133 | AF15: =EXP(-(AD15^2)/(2*Yardstick^2)) -> 0.92768491 | AG15: =AF15/$E$7 -> 0.0040051867 | AH15: -0.3351623 | AI15: 0 | AJ15: -0.25167536 | AK15: 0 | AL15: -0.7379041 | AM15: 0 | AN15: 1.8476021 | AO15: 0 | AP15: 0.60494629 | AQ15: 1
A16: 6 | B16: Nathan Mackinnon | C16: 2020-21 & 2021-22 | D16: 26 | E16: 1 | F16: 0.3562191 | G16: -0.1126197 | H16: 0.16051761 | I16: 0.00012244434 | J16: 0.37052115 | K16: 19.992183 | L16: 4.2984445 | M16: -0.47765556 | N16: =(F16-Settings!$D$18)/Settings!$E$18 -> 0.58657588 | O16: =(G16-Settings!$D$19)/Settings!$E$19 -> -0.44151703 | P16: =(H16-Settings!$D$20)/Settings!$E$20 -> 0.97297777 | Q16: =(I16-Settings!$D$21)/Settings!$E$21 -> 0.03771486 | R16: =(J16-Settings!$D$22)/Settings!$E$22 -> 0.33002229 | S16: =(K16-Settings!$D$23)/Settings!$E$23 -> 1.6450412 | T16: =(L16-Settings!$D$24)/Settings!$E$24 -> 2.0672727 | U16: =(M16-Settings!$D$25)/Settings!$E$25 -> -0.28616597 | V16: =Settings!$B$18*(N16-F$6)^2 -> 0.058284595 | W16: =Settings!$B$19*(O16-G$6)^2 -> 0.17881704 | X16: =Settings!$B$20*(P16-H$6)^2 -> 0.33207544 | Y16: =Settings!$B$21*(Q16-I$6)^2 -> 0.16108268 | Z16: =Settings!$B$22*(R16-J$6)^2 -> 0.0062768198 | AA16: =Settings!$B$23*(S16-K$6)^2 -> 0.0068558828 | AB16: =Settings!$B$24*(T16-L$6)^2 -> 0.29274248 | AC16: =Settings!$B$25*(U16-M$6)^2 -> 0.010864117 | AD16: =SQRT(SUM(V16:AC16)) -> 1.0232297 | AE16: =AD16/Yardstick -> 0.40501287 | AF16: =EXP(-(AD16^2)/(2*Yardstick^2)) -> 0.92125564 | AG16: =AF16/$E$7 -> 0.003977429 | AH16: 0.63124458 | AI16: 1 | AJ16: 2.6460712 | AK16: 1 | AL16: -0.20769262 | AM16: 1 | AN16: -0.66171672 | AO16: 1
A17: 7 | B17: Mathew Barzal | C17: 2022-23 & 2023-24 | D17: 26 | E17: 1 | F17: 0.38049616 | G17: -0.13031032 | H17: 0.2594289 | I17: 1.2102934e-05 | J17: 0.22975252 | K17: 18.918357 | L17: 2.6804045 | M17: 0.069187325 | N17: =(F17-Settings!$D$18)/Settings!$E$18 -> 0.67346197 | O17: =(G17-Settings!$D$19)/Settings!$E$19 -> -0.51521843 | P17: =(H17-Settings!$D$20)/Settings!$E$20 -> 1.8691331 | Q17: =(I17-Settings!$D$21)/Settings!$E$21 -> 0.036357958 | R17: =(J17-Settings!$D$22)/Settings!$E$22 -> -0.048722344 | S17: =(K17-Settings!$D$23)/Settings!$E$23 -> 1.2721263 | T17: =(L17-Settings!$D$24)/Settings!$E$24 -> 0.94863306 | U17: =(M17-Settings!$D$25)/Settings!$E$25 -> 0.08263096 | V17: =Settings!$B$18*(N17-F$6)^2 -> 0.078556131 | W17: =Settings!$B$19*(O17-G$6)^2 -> 0.20777908 | X17: =Settings!$B$20*(P17-H$6)^2 -> 0.030795702 | Y17: =Settings!$B$21*(Q17-I$6)^2 -> 0.16059595 | Z17: =Settings!$B$22*(R17-J$6)^2 -> 0.0081276296 | AA17: =Settings!$B$23*(S17-K$6)^2 -> 0.20767627 | AB17: =Settings!$B$24*(T17-L$6)^2 -> 0.33360187 | AC17: =Settings!$B$25*(U17-M$6)^2 -> 0.069995092 | AD17: =SQRT(SUM(V17:AC17)) -> 1.0474387 | AE17: =AD17/Yardstick -> 0.41459521 | AF17: =EXP(-(AD17^2)/(2*Yardstick^2)) -> 0.91764507 | AG17: =AF17/$E$7 -> 0.0039618407 | AH17: -0.3712362 | AI17: 1 | AJ17: -0.089494464 | AK17: 1
A18: 8 | B18: Ryan Callahan | C18: 2010-11 & 2011-12 | D18: 26 | E18: 0 | F18: 0.11597382 | G18: -0.024835333 | H18: 0.27595417 | I18: 0.03069616 | J18: 0.55254051 | K18: 19.937255 | L18: 3.2605522 | M18: -1.4472951 | N18: =(F18-Settings!$D$18)/Settings!$E$18 -> -0.27324699 | O18: =(G18-Settings!$D$19)/Settings!$E$19 -> -0.075796175 | P18: =(H18-Settings!$D$20)/Settings!$E$20 -> 2.0188553 | Q18: =(I18-Settings!$D$21)/Settings!$E$21 -> 0.41368925 | R18: =(J18-Settings!$D$22)/Settings!$E$22 -> 0.81975396 | S18: =(K18-Settings!$D$23)/Settings!$E$23 -> 1.6259659 | T18: =(L18-Settings!$D$24)/Settings!$E$24 -> 1.3497209 | U18: =(M18-Settings!$D$25)/Settings!$E$25 -> -0.9401017 | V18: =Settings!$B$18*(N18-F$6)^2 -> 0.020478312 | W18: =Settings!$B$19*(O18-G$6)^2 -> 0.067242869 | X18: =Settings!$B$20*(P18-H$6)^2 -> 0.011778598 | Y18: =Settings!$B$21*(Q18-I$6)^2 -> 0.32432106 | Z18: =Settings!$B$22*(R18-J$6)^2 -> 0.088947719 | AA18: =Settings!$B$23*(S18-K$6)^2 -> 0.010378615 | AB18: =Settings!$B$24*(T18-L$6)^2 -> 0.031150466 | AC18: =Settings!$B$25*(U18-M$6)^2 -> 0.5748169 | AD18: =SQRT(SUM(V18:AC18)) -> 1.062598 | AE18: =AD18/Yardstick -> 0.42059556 | AF18: =EXP(-(AD18^2)/(2*Yardstick^2)) -> 0.91534859 | AG18: =AF18/$E$7 -> 0.0039519259 | AH18: -0.41966118 | AI18: 0 | AJ18: -0.39013486 | AK18: 0 | AL18: -0.21604564 | AM18: 0 | AN18: -1.040292 | AO18: 0
A19: 9 | B19: John Tavares | C19: 2015-16 & 2016-17 | D19: 26 | E19: 0 | F19: 0.46710781 | G19: -0.14957658 | H19: 0.16998335 | I19: 0.014638972 | J19: 0.19869328 | K19: 19.59129 | L19: 3.0032701 | M19: -0.18257105 | N19: =(F19-Settings!$D$18)/Settings!$E$18 -> 0.98343968 | O19: =(G19-Settings!$D$19)/Settings!$E$19 -> -0.59548412 | P19: =(H19-Settings!$D$20)/Settings!$E$20 -> 1.0587392 | Q19: =(I19-Settings!$D$21)/Settings!$E$21 -> 0.21622906 | R19: =(J19-Settings!$D$22)/Settings!$E$22 -> -0.13228867 | S19: =(K19-Settings!$D$23)/Settings!$E$23 -> 1.5058204 | T19: =(L19-Settings!$D$24)/Settings!$E$24 -> 1.1718477 | U19: =(M19-Settings!$D$25)/Settings!$E$25 -> -0.087157694 | V19: =Settings!$B$18*(N19-F$6)^2 -> 0.17548133 | W19: =Settings!$B$19*(O19-G$6)^2 -> 0.24179231 | X19: =Settings!$B$20*(P19-H$6)^2 -> 0.28934308 | Y19: =Settings!$B$21*(Q19-I$6)^2 -> 0.23153905 | Z19: =Settings!$B$22*(R19-J$6)^2 -> 0.016262719 | AA19: =Settings!$B$23*(S19-K$6)^2 -> 0.049293336 | AB19: =Settings!$B$24*(T19-L$6)^2 -> 0.12557676 | AC19: =Settings!$B$25*(U19-M$6)^2 -> 0.0089827179 | AD19: =SQRT(SUM(V19:AC19)) -> 1.066898 | AE19: =AD19/Yardstick -> 0.42229756 | AF19: =EXP(-(AD19^2)/(2*Yardstick^2)) -> 0.91469224 | AG19: =AF19/$E$7 -> 0.0039490922 | AH19: 0.1003808 | AI19: 0 | AJ19: 0.94778134 | AK19: 1 | AL19: -0.065618058 | AM19: 1 | AN19: -1.4225728 | AO19: 1 | AP19: -0.61502027 | AQ19: 1
A20: 10 | B20: Corey Perry | C20: 2010-11 & 2011-12 | D20: 26 | E20: 0 | F20: 0.16664295 | G20: 0.0014466935 | H20: 0.15449131 | I20: 0.012900591 | J20: 0.66451846 | K20: 21.203909 | L20: 4.2475294 | M20: -0.45197796 | N20: =(F20-Settings!$D$18)/Settings!$E$18 -> -0.091905346 | O20: =(G20-Settings!$D$19)/Settings!$E$19 -> 0.033698096 | P20: =(H20-Settings!$D$20)/Settings!$E$20 -> 0.91837839 | Q20: =(I20-Settings!$D$21)/Settings!$E$21 -> 0.19485166 | R20: =(J20-Settings!$D$22)/Settings!$E$22 -> 1.1210359 | S20: =(K20-Settings!$D$23)/Settings!$E$23 -> 2.0658459 | T20: =(L20-Settings!$D$24)/Settings!$E$24 -> 2.0320722 | U20: =(M20-Settings!$D$25)/Settings!$E$25 -> -0.26884871 | V20: =Settings!$B$18*(N20-F$6)^2 -> 0.0038444966 | W20: =Settings!$B$19*(O20-G$6)^2 -> 0.044245008 | X20: =Settings!$B$20*(P20-H$6)^2 -> 0.36081342 | Y20: =Settings!$B$21*(Q20-I$6)^2 -> 0.22242994 | Z20: =Settings!$B$22*(R20-J$6)^2 -> 0.18747031 | AA20: =Settings!$B$23*(S20-K$6)^2 -> 0.11424705 | AB20: =Settings!$B$24*(T20-L$6)^2 -> 0.25589069 | AC20: =Settings!$B$25*(U20-M$6)^2 -> 0.0075540116 | AD20: =SQRT(SUM(V20:AC20)) -> 1.0938441 | AE20: =AD20/Yardstick -> 0.43296333 | AF20: =EXP(-(AD20^2)/(2*Yardstick^2)) -> 0.91052983 | AG20: =AF20/$E$7 -> 0.0039311214 | AH20: -1.5098182 | AI20: 0 | AJ20: 0.71003937 | AK20: 0 | AL20: 1.294527 | AM20: 0 | AN20: -1.5072786 | AO20: 0 | AP20: -1.8452489 | AQ20: 0
A21: 11 | B21: Kyle Okposo | C21: 2013-14 & 2014-15 | D21: 26 | E21: 0 | F21: 0.32562787 | G21: -0.168693 | H21: 0.15778631 | I21: -0.00076710586 | J21: 0.34712571 | K21: 19.495929 | L21: 2.7267188 | M21: -0.59461491 | N21: =(F21-Settings!$D$18)/Settings!$E$18 -> 0.47709178 | O21: =(G21-Settings!$D$19)/Settings!$E$19 -> -0.67512556 | P21: =(H21-Settings!$D$20)/Settings!$E$20 -> 0.94823174 | Q21: =(I21-Settings!$D$21)/Settings!$E$21 -> 0.026775788 | R21: =(J21-Settings!$D$22)/Settings!$E$22 -> 0.26707575 | S21: =(K21-Settings!$D$23)/Settings!$E$23 -> 1.4727035 | T21: =(L21-Settings!$D$24)/Settings!$E$24 -> 0.9806527 | U21: =(M21-Settings!$D$25)/Settings!$E$25 -> -0.36504466 | V21: =Settings!$B$18*(N21-F$6)^2 -> 0.037040562 | W21: =Settings!$B$19*(O21-G$6)^2 -> 0.27808806 | X21: =Settings!$B$20*(P21-H$6)^2 -> 0.34495258 | Y21: =Settings!$B$21*(Q21-I$6)^2 -> 0.15717971 | Z21: =Settings!$B$22*(R21-J$6)^2 -> 0.0026087409 | AA21: =Settings!$B$23*(S21-K$6)^2 -> 0.065095351 | AB21: =Settings!$B$24*(T21-L$6)^2 -> 0.29763914 | AC21: =Settings!$B$25*(U21-M$6)^2 -> 0.033529186 | AD21: =SQRT(SUM(V21:AC21)) -> 1.1027844 | AE21: =AD21/Yardstick -> 0.43650204 | AF21: =EXP(-(AD21^2)/(2*Yardstick^2)) -> 0.90913015 | AG21: =AF21/$E$7 -> 0.0039250784 | AH21: -0.23118646 | AI21: 0 | AJ21: 0.098558957 | AK21: 0 | AL21: -1.2201049 | AM21: 0 | AN21: -1.1180921 | AO21: 1 | AP21: 0.60967124 | AQ21: 1
A22: 12 | B22: William Nylander | C22: 2021-22 & 2022-23 | D22: 26 | E22: 1 | F22: 0.34222721 | G22: -0.098390263 | H22: 0.25060226 | I22: 0.0040602 | J22: 0.30472006 | K22: 17.839366 | L22: 3.9369356 | M22: -0.13967572 | N22: =(F22-Settings!$D$18)/Settings!$E$18 -> 0.53649979 | O22: =(G22-Settings!$D$19)/Settings!$E$19 -> -0.38223539 | P22: =(H22-Settings!$D$20)/Settings!$E$20 -> 1.7891621 | Q22: =(I22-Settings!$D$21)/Settings!$E$21 -> 0.086138652 | R22: =(J22-Settings!$D$22)/Settings!$E$22 -> 0.15298136 | S22: =(K22-Settings!$D$23)/Settings!$E$23 -> 0.8974174 | T22: =(L22-Settings!$D$24)/Settings!$E$24 -> 1.8173417 | U22: =(M22-Settings!$D$25)/Settings!$E$25 -> -0.0582286 | V22: =Settings!$B$18*(N22-F$6)^2 -> 0.047972965 | W22: =Settings!$B$19*(O22-G$6)^2 -> 0.15709814 | X22: =Settings!$B$20*(P22-H$6)^2 -> 0.044627048 | Y22: =Settings!$B$21*(Q22-I$6)^2 -> 0.1789348 | Z22: =Settings!$B$22*(R22-J$6)^2 -> 2.6288406e-09 | AA22: =Settings!$B$23*(S22-K$6)^2 -> 0.68960407 | AB22: =Settings!$B$24*(T22-L$6)^2 -> 0.08475428 | AC22: =Settings!$B$25*(U22-M$6)^2 -> 0.015303248 | AD22: =SQRT(SUM(V22:AC22)) -> 1.1037638 | AE22: =AD22/Yardstick -> 0.43688973 | AF22: =EXP(-(AD22^2)/(2*Yardstick^2)) -> 0.90897625 | AG22: =AF22/$E$7 -> 0.0039244139 | AH22: 0.23928665 | AI22: 1 | AJ22: 0.23503102 | AK22: 1 | AL22: -0.93913551 | AM22: 1
A23: 13 | B23: Ryan Kesler | C23: 2009-10 & 2010-11 | D23: 26 | E23: 0 | F23: 0.2425076 | G23: -0.016935511 | H23: 0.23719868 | I23: -0.10298328 | J23: 0.40037493 | K23: 19.499284 | L23: 3.5435546 | M23: 1.1697164 | N23: =(F23-Settings!$D$18)/Settings!$E$18 -> 0.17960952 | O23: =(G23-Settings!$D$19)/Settings!$E$19 -> -0.042884512 | P23: =(H23-Settings!$D$20)/Settings!$E$20 -> 1.667723 | Q23: =(I23-Settings!$D$21)/Settings!$E$21 -> -1.2302079 | R23: =(J23-Settings!$D$22)/Settings!$E$22 -> 0.41034529 | S23: =(K23-Settings!$D$23)/Settings!$E$23 -> 1.4738688 | T23: =(L23-Settings!$D$24)/Settings!$E$24 -> 1.545376 | U23: =(M23-Settings!$D$25)/Settings!$E$25 -> 0.82484001 | V23: =Settings!$B$18*(N23-F$6)^2 -> 0.0035308711 | W23: =Settings!$B$19*(O23-G$6)^2 -> 0.059826106 | X23: =Settings!$B$20*(P23-H$6)^2 -> 0.070522296 | Y23: =Settings!$B$21*(Q23-I$6)^2 -> 0.027450273 | Z23: =Settings!$B$22*(R23-J$6)^2 -> 0.013259043 | AA23: =Settings!$B$23*(S23-K$6)^2 -> 0.064502091 | AB23: =Settings!$B$24*(T23-L$6)^2 -> 0.00036711022 | AC23: =Settings!$B$25*(U23-M$6)^2 -> 1.0135957 | AD23: =SQRT(SUM(V23:AC23)) -> 1.1193987 | AE23: =AD23/Yardstick -> 0.44307831 | AF23: =EXP(-(AD23^2)/(2*Yardstick^2)) -> 0.90650458 | AG23: =AF23/$E$7 -> 0.0039137428 | AH23: -0.94137902 | AI23: 0 | AN23: -0.21824838 | AO23: 0 | AP23: 0.1182402 | AQ23: 0
A24: 14 | B24: Jamie Benn | C24: 2014-15 & 2015-16 | D24: 26 | E24: 0 | F24: 0.3449204 | G24: -0.058298587 | H24: 0.15521663 | I24: 0.019743575 | J24: 0.42182081 | K24: 19.319614 | L24: 4.40853 | M24: -0.032292762 | N24: =(F24-Settings!$D$18)/Settings!$E$18 -> 0.54613855 | O24: =(G24-Settings!$D$19)/Settings!$E$19 -> -0.21520836 | P24: =(H24-Settings!$D$20)/Settings!$E$20 -> 0.92494991 | Q24: =(I24-Settings!$D$21)/Settings!$E$21 -> 0.27900193 | R24: =(J24-Settings!$D$22)/Settings!$E$22 -> 0.46804643 | S24: =(K24-Settings!$D$23)/Settings!$E$23 -> 1.4114734 | T24: =(L24-Settings!$D$24)/Settings!$E$24 -> 2.1433808 | U24: =(M24-Settings!$D$25)/Settings!$E$25 -> 0.01419166 | V24: =Settings!$B$18*(N24-F$6)^2 -> 0.049879817 | W24: =Settings!$B$19*(O24-G$6)^2 -> 0.10346472 | X24: =Settings!$B$20*(P24-H$6)^2 -> 0.35729142 | Y24: =Settings!$B$21*(Q24-I$6)^2 -> 0.25934364 | Z24: =Settings!$B$22*(R24-J$6)^2 -> 0.019867651 | AA24: =Settings!$B$23*(S24-K$6)^2 -> 0.10008873 | AB24: =Settings!$B$24*(T24-L$6)^2 -> 0.38089254 | AC24: =Settings!$B$25*(U24-M$6)^2 -> 0.038465626 | AD24: =SQRT(SUM(V24:AC24)) -> 1.1442439 | AE24: =AD24/Yardstick -> 0.45291249 | AF24: =EXP(-(AD24^2)/(2*Yardstick^2)) -> 0.90251961 | AG24: =AF24/$E$7 -> 0.003896538 | AH24: -1.4236101 | AI24: 0 | AJ24: -0.48071519 | AK24: 0 | AL24: 0.31286203 | AM24: 1 | AN24: -0.46999239 | AO24: 1 | AP24: -0.28865244 | AQ24: 1
A25: 15 | B25: Jon Huberdeau | C25: 2018-19 & 2019-20 | D25: 26 | E25: 1 | F25: 0.22924031 | G25: -0.071534159 | H25: 0.17667476 | I25: 0.0012995536 | J25: 0.52125121 | K25: 18.086755 | L25: 2.8771261 | M25: -0.13865212 | N25: =(F25-Settings!$D$18)/Settings!$E$18 -> 0.13212672 | O25: =(G25-Settings!$D$19)/Settings!$E$19 -> -0.27034944 | P25: =(H25-Settings!$D$20)/Settings!$E$20 -> 1.1193647 | Q25: =(I25-Settings!$D$21)/Settings!$E$21 -> 0.052190135 | R25: =(J25-Settings!$D$22)/Settings!$E$22 -> 0.73556862 | S25: =(K25-Settings!$D$23)/Settings!$E$23 -> 0.98332988 | T25: =(L25-Settings!$D$24)/Settings!$E$24 -> 1.0846375 | U25: =(M25-Settings!$D$25)/Settings!$E$25 -> -0.057538273 | V25: =Settings!$B$18*(N25-F$6)^2 -> 0.0014581844 | W25: =Settings!$B$19*(O25-G$6)^2 -> 0.11993696 | X25: =Settings!$B$20*(P25-H$6)^2 -> 0.26091014 | Y25: =Settings!$B$21*(Q25-I$6)^2 -> 0.16632091 | Z25: =Settings!$B$22*(R25-J$6)^2 -> 0.067908302 | AA25: =Settings!$B$23*(S25-K$6)^2 -> 0.55429745 | AB25: =Settings!$B$24*(T25-L$6)^2 -> 0.19499146 | AC25: =Settings!$B$25*(U25-M$6)^2 -> 0.01547452 | AD25: =SQRT(SUM(V25:AC25)) -> 1.1752863 | AE25: =AD25/Yardstick -> 0.46519963 | AF25: =EXP(-(AD25^2)/(2*Yardstick^2)) -> 0.89744329 | AG25: =AF25/$E$7 -> 0.0038746215 | AH25: 0.4674795 | AI25: 1 | AJ25: -0.33301118 | AK25: 1 | AL25: -1.4501321 | AM25: 1 | AN25: -0.75336464 | AO25: 1 | AP25: 1.1487507 | AQ25: 1
A26: 16 | B26: Artemi Panarin | C26: 2016-17 & 2017-18 | D26: 26 | E26: 0 | F26: 0.30304475 | G26: -0.05440448 | H26: 0.099305898 | I26: 6.4957469e-06 | J26: 0.54323838 | K26: 19.231084 | L26: 3.0895536 | M26: -1.0740975 | N26: =(F26-Settings!$D$18)/Settings!$E$18 -> 0.3962682 | O26: =(G26-Settings!$D$19)/Settings!$E$19 -> -0.19898501 | P26: =(H26-Settings!$D$20)/Settings!$E$20 -> 0.41838792 | Q26: =(I26-Settings!$D$21)/Settings!$E$21 -> 0.036289005 | R26: =(J26-Settings!$D$22)/Settings!$E$22 -> 0.79472612 | S26: =(K26-Settings!$D$23)/Settings!$E$23 -> 1.380729 | T26: =(L26-Settings!$D$24)/Settings!$E$24 -> 1.2315002 | U26: =(M26-Settings!$D$25)/Settings!$E$25 -> -0.68841305 | V26: =Settings!$B$18*(N26-F$6)^2 -> 0.024434017 | W26: =Settings!$B$19*(O26-G$6)^2 -> 0.098849889 | X26: =Settings!$B$20*(P26-H$6)^2 -> 0.67943751 | Y26: =Settings!$B$21*(Q26-I$6)^2 -> 0.16057124 | Z26: =Settings!$B$22*(R26-J$6)^2 -> 0.082396701 | AA26: =Settings!$B$23*(S26-K$6)^2 -> 0.12048705 | AB26: =Settings!$B$24*(T26-L$6)^2 -> 0.086857286 | AC26: =Settings!$B$25*(U26-M$6)^2 -> 0.25652012 | AD26: =SQRT(SUM(V26:AC26)) -> 1.228639 | AE26: =AD26/Yardstick -> 0.48631759 | AF26: =EXP(-(AD26^2)/(2*Yardstick^2)) -> 0.88847177 | AG26: =AF26/$E$7 -> 0.0038358879 | AH26: 0.6119958 | AI26: 1 | AJ26: 1.2355766 | AK26: 1 | AL26: -0.59375804 | AM26: 1 | AN26: -1.9216072 | AO26: 1 | AP26: 0.09099142 | AQ26: 1
A27: 17 | B27: Dylan Larkin | C27: 2021-22 & 2022-23 | D27: 26 | E27: 1 | F27: 0.29148679 | G27: 0.018638673 | H27: 0.1724683 | I27: -0.010095224 | J27: 0.50731102 | K27: 18.842053 | L27: 4.1285941 | M27: -1.4718056 | N27: =(F27-Settings!$D$18)/Settings!$E$18 -> 0.35490298 | O27: =(G27-Settings!$D$19)/Settings!$E$19 -> 0.10532207 | P27: =(H27-Settings!$D$20)/Settings!$E$20 -> 1.0812533 | Q27: =(I27-Settings!$D$21)/Settings!$E$21 -> -0.087934948 | R27: =(J27-Settings!$D$22)/Settings!$E$22 -> 0.69806187 | S27: =(K27-Settings!$D$23)/Settings!$E$23 -> 1.2456275 | T27: =(L27-Settings!$D$24)/Settings!$E$24 -> 1.9498457 | U27: =(M27-Settings!$D$25)/Settings!$E$25 -> -0.95663182 | V27: =Settings!$B$18*(N27-F$6)^2 -> 0.018992906 | W27: =Settings!$B$19*(O27-G$6)^2 -> 0.031795796 | X27: =Settings!$B$20*(P27-H$6)^2 -> 0.27861251 | Y27: =Settings!$B$21*(Q27-I$6)^2 -> 0.11913458 | Z27: =Settings!$B$22*(R27-J$6)^2 -> 0.059447551 | AA27: =Settings!$B$23*(S27-K$6)^2 -> 0.23253027 | AB27: =Settings!$B$24*(T27-L$6)^2 -> 0.17946229 | AC27: =Settings!$B$25*(U27-M$6)^2 -> 0.60015532 | AD27: =SQRT(SUM(V27:AC27)) -> 1.232936 | AE27: =AD27/Yardstick -> 0.48801843 | AF27: =EXP(-(AD27^2)/(2*Yardstick^2)) -> 0.8877359 | AG27: =AF27/$E$7 -> 0.0038327109 | AH27: 0.14761959 | AI27: 1 | AJ27: -0.21884885 | AK27: 1 | AL27: -1.3468144 | AM27: 1
A28: 18 | B28: Mikko Rantanen | C28: 2021-22 & 2022-23 | D28: 26 | E28: 1 | F28: 0.22356683 | G28: -0.12027257 | H28: 0.13687945 | I28: -2.5123729e-05 | J28: 0.51925603 | K28: 20.740658 | L28: 4.718305 | M28: -0.0018451867 | N28: =(F28-Settings!$D$18)/Settings!$E$18 -> 0.11182168 | O28: =(G28-Settings!$D$19)/Settings!$E$19 -> -0.47339985 | P28: =(H28-Settings!$D$20)/Settings!$E$20 -> 0.75881152 | Q28: =(I28-Settings!$D$21)/Settings!$E$21 -> 0.03590017 | R28: =(J28-Settings!$D$22)/Settings!$E$22 -> 0.73020049 | S28: =(K28-Settings!$D$23)/Settings!$E$23 -> 1.9049694 | T28: =(L28-Settings!$D$24)/Settings!$E$24 -> 2.3575451 | U28: =(M28-Settings!$D$25)/Settings!$E$25 -> 0.034725844 | V28: =Settings!$B$18*(N28-F$6)^2 -> 0.00084712974 | W28: =Settings!$B$19*(O28-G$6)^2 -> 0.1910792 | X28: =Settings!$B$20*(P28-H$6)^2 -> 0.45163499 | Y28: =Settings!$B$21*(Q28-I$6)^2 -> 0.16043191 | Z28: =Settings!$B$22*(R28-J$6)^2 -> 0.066662858 | AA28: =Settings!$B$23*(S28-K$6)^2 -> 0.031374325 | AB28: =Settings!$B$24*(T28-L$6)^2 -> 0.69110838 | AC28: =Settings!$B$25*(U28-M$6)^2 -> 0.046941876 | AD28: =SQRT(SUM(V28:AC28)) -> 1.2806563 | AE28: =AD28/Yardstick -> 0.506907 | AF28: =EXP(-(AD28^2)/(2*Yardstick^2)) -> 0.87943348 | AG28: =AF28/$E$7 -> 0.003796866 | AH28: -0.76785446 | AI28: 1 | AJ28: -2.7408486 | AK28: 1 | AL28: -0.55932765 | AM28: 1
A29: 19 | B29: Mark Scheifele | C29: 2018-19 & 2019-20 | D29: 26 | E29: 1 | F29: 0.21775739 | G29: -0.20061631 | H29: 0.10929928 | I29: -0.012682744 | J29: 0.45964428 | K29: 21.019499 | L29: 2.8622566 | M29: -1.0857048 | N29: =(F29-Settings!$D$18)/Settings!$E$18 -> 0.091030054 | O29: =(G29-Settings!$D$19)/Settings!$E$19 -> -0.80812211 | P29: =(H29-Settings!$D$20)/Settings!$E$20 -> 0.50892987 | Q29: =(I29-Settings!$D$21)/Settings!$E$21 -> -0.11975448 | R29: =(J29-Settings!$D$22)/Settings!$E$22 -> 0.56981227 | S29: =(K29-Settings!$D$23)/Settings!$E$23 -> 2.0018044 | T29: =(L29-Settings!$D$24)/Settings!$E$24 -> 1.0743574 | U29: =(M29-Settings!$D$25)/Settings!$E$25 -> -0.69624112 | V29: =Settings!$B$18*(N29-F$6)^2 -> 0.00039232492 | W29: =Settings!$B$19*(O29-G$6)^2 -> 0.34435585 | X29: =Settings!$B$20*(P29-H$6)^2 -> 0.61432427 | Y29: =Settings!$B$21*(Q29-I$6)^2 -> 0.10951377 | Z29: =Settings!$B$22*(R29-J$6)^2 -> 0.03476872 | AA29: =Settings!$B$23*(S29-K$6)^2 -> 0.075055707 | AB29: =Settings!$B$24*(T29-L$6)^2 -> 0.20417606 | AC29: =Settings!$B$25*(U29-M$6)^2 -> 0.26451089 | AD29: =SQRT(SUM(V29:AC29)) -> 1.283393 | AE29: =AD29/Yardstick -> 0.50799022 | AF29: =EXP(-(AD29^2)/(2*Yardstick^2)) -> 0.87895021 | AG29: =AF29/$E$7 -> 0.0037947795 | AH29: -0.24542502 | AI29: 1 | AJ29: 0.42880443 | AK29: 1 | AL29: 0.7230788 | AM29: 1 | AN29: -0.84999619 | AO29: 1 | AP29: -0.55870973 | AQ29: 1
A30: 20 | B30: Phil Kessel | C30: 2012-13 & 2013-14 | D30: 26 | E30: 0 | F30: 0.28244394 | G30: -0.20213645 | H30: 0.075962874 | I30: 1.5674202e-05 | J30: 0.43944106 | K30: 19.802949 | L30: 3.5404889 | M30: 0.40151811 | N30: =(F30-Settings!$D$18)/Settings!$E$18 -> 0.3225392 | O30: =(G30-Settings!$D$19)/Settings!$E$19 -> -0.81445521 | P30: =(H30-Settings!$D$20)/Settings!$E$20 -> 0.20689564 | Q30: =(I30-Settings!$D$21)/Settings!$E$21 -> 0.036401875 | R30: =(J30-Settings!$D$22)/Settings!$E$22 -> 0.51545456 | S30: =(K30-Settings!$D$23)/Settings!$E$23 -> 1.5793245 | T30: =(L30-Settings!$D$24)/Settings!$E$24 -> 1.5432565 | U30: =(M30-Settings!$D$25)/Settings!$E$25 -> 0.30675855 | V30: =Settings!$B$18*(N30-F$6)^2 -> 0.015213059 | W30: =Settings!$B$19*(O30-G$6)^2 -> 0.3476879 | X30: =Settings!$B$20*(P30-H$6)^2 -> 0.84430778 | Y30: =Settings!$B$21*(Q30-I$6)^2 -> 0.16061169 | Z30: =Settings!$B$22*(R30-J$6)^2 -> 0.02629399 | AA30: =Settings!$B$23*(S30-K$6)^2 -> 0.02205728 | AB30: =Settings!$B$24*(T30-L$6)^2 -> 0.00029038271 | AC30: =Settings!$B$25*(U30-M$6)^2 -> 0.23882128 | AD30: =SQRT(SUM(V30:AC30)) -> 1.2865782 | AE30: =AD30/Yardstick -> 0.50925096 | AF30: =EXP(-(AD30^2)/(2*Yardstick^2)) -> 0.87838677 | AG30: =AF30/$E$7 -> 0.0037923469 | AH30: -1.2910538 | AI30: 0 | AJ30: -0.92501285 | AK30: 0 | AL30: 0.10456436 | AM30: 0 | AN30: 0.47071941 | AO30: 0 | AP30: 0.28731504 | AQ30: 1
A31: 21 | B31: Jason Spezza | C31: 2008-09 & 2009-10 | D31: 26 | E31: 0 | F31: 0.234805 | G31: -0.15915123 | H31: 0.096536599 | I31: -0.0027039284 | J31: 0.50680324 | K31: 18.937262 | L31: 2.6257775 | M31: -0.05830565 | N31: =(F31-Settings!$D$18)/Settings!$E$18 -> 0.15204239 | O31: =(G31-Settings!$D$19)/Settings!$E$19 -> -0.63537334 | P31: =(H31-Settings!$D$20)/Settings!$E$20 -> 0.39329754 | Q31: =(I31-Settings!$D$21)/Settings!$E$21 -> 0.002958085 | R31: =(J31-Settings!$D$22)/Settings!$E$22 -> 0.69669566 | S31: =(K31-Settings!$D$23)/Settings!$E$23 -> 1.2786914 | T31: =(L31-Settings!$D$24)/Settings!$E$24 -> 0.91086644 | U31: =(M31-Settings!$D$25)/Settings!$E$25 -> -0.0033517218 | V31: =Settings!$B$18*(N31-F$6)^2 -> 0.0022177262 | W31: =Settings!$B$19*(O31-G$6)^2 -> 0.25965426 | X31: =Settings!$B$20*(P31-H$6)^2 -> 0.69806151 | Y31: =Settings!$B$21*(Q31-I$6)^2 -> 0.14884733 | Z31: =Settings!$B$22*(R31-J$6)^2 -> 0.059149985 | AA31: =Settings!$B$23*(S31-K$6)^2 -> 0.20173577 | AB31: =Settings!$B$24*(T31-L$6)^2 -> 0.37865489 | AC31: =Settings!$B$25*(U31-M$6)^2 -> 0.03189195 | AD31: =SQRT(SUM(V31:AC31)) -> 1.3342464 | AE31: =AD31/Yardstick -> 0.52811891 | AF31: =EXP(-(AD31^2)/(2*Yardstick^2)) -> 0.86983235 | AG31: =AF31/$E$7 -> 0.0037554141 | AH31: -0.02041842 | AI31: 0 | AJ31: 0.13215851 | AK31: 0 | AP31: 0.4066143 | AQ31: 0
A32: 22 | B32: Alex Steen | C32: 2009-10 & 2010-11 | D32: 26 | E32: 0 | F32: 0.045356957 | G32: 0.13884342 | H32: 0.15578696 | I32: -0.019026005 | J32: 0.64098665 | K32: 17.533452 | L32: 3.4099875 | M32: -1.0314474 | N32: =(F32-Settings!$D$18)/Settings!$E$18 -> -0.52598035 | O32: =(G32-Settings!$D$19)/Settings!$E$19 -> 0.60611039 | P32: =(H32-Settings!$D$20)/Settings!$E$20 -> 0.93011723 | Q32: =(I32-Settings!$D$21)/Settings!$E$21 -> -0.19775951 | R32: =(J32-Settings!$D$22)/Settings!$E$22 -> 1.0577225 | S32: =(K32-Settings!$D$23)/Settings!$E$23 -> 0.79118062 | T32: =(L32-Settings!$D$24)/Settings!$E$24 -> 1.4530337 | U32: =(M32-Settings!$D$25)/Settings!$E$25 -> -0.65964934 | V32: =Settings!$B$18*(N32-F$6)^2 -> 0.065601678 | W32: =Settings!$B$19*(O32-G$6)^2 -> 0.0020835197 | X32: =Settings!$B$20*(P32-H$6)^2 -> 0.35453414 | Y32: =Settings!$B$21*(Q32-I$6)^2 -> 0.087641891 | Z32: =Settings!$B$22*(R32-J$6)^2 -> 0.16375278 | AA32: =Settings!$B$23*(S32-K$6)^2 -> 0.87733347 | AB32: =Settings!$B$24*(T32-L$6)^2 -> 0.0053556226 | AC32: =Settings!$B$25*(U32-M$6)^2 -> 0.22821109 | AD32: =SQRT(SUM(V32:AC32)) -> 1.3358571 | AE32: =AD32/Yardstick -> 0.52875646 | AF32: =EXP(-(AD32^2)/(2*Yardstick^2)) -> 0.86953934 | AG32: =AF32/$E$7 -> 0.0037541491 | AH32: 0.015483206 | AI32: 0 | AJ32: -0.78721689 | AK32: 0 | AL32: 1.4884603 | AM32: 0 | AN32: 1.2673512 | AO32: 0 | AP32: -3.1875179 | AQ32: 0
A33: 23 | B33: Jon Toews | C33: 2013-14 & 2014-15 | D33: 26 | E33: 0 | F33: 0.44959952 | G33: -0.026377285 | H33: 0.10353327 | I33: -0.015400205 | J33: 0.40508971 | K33: 19.510828 | L33: 4.1362305 | M33: -1.5167123 | N33: =(F33-Settings!$D$18)/Settings!$E$18 -> 0.9207786 | O33: =(G33-Settings!$D$19)/Settings!$E$19 -> -0.082220145 | P33: =(H33-Settings!$D$20)/Settings!$E$20 -> 0.45668876 | Q33: =(I33-Settings!$D$21)/Settings!$E$21 -> -0.15317193 | R33: =(J33-Settings!$D$22)/Settings!$E$22 -> 0.42303064 | S33: =(K33-Settings!$D$23)/Settings!$E$23 -> 1.4778777 | T33: =(L33-Settings!$D$24)/Settings!$E$24 -> 1.9551252 | U33: =(M33-Settings!$D$25)/Settings!$E$25 -> -0.98691744 | V33: =Settings!$B$18*(N33-F$6)^2 -> 0.15278876 | W33: =Settings!$B$19*(O33-G$6)^2 -> 0.068741072 | X33: =Settings!$B$20*(P33-H$6)^2 -> 0.65149329 | Y33: =Settings!$B$21*(Q33-I$6)^2 -> 0.099845828 | Z33: =Settings!$B$22*(R33-J$6)^2 -> 0.014597709 | AA33: =Settings!$B$23*(S33-K$6)^2 -> 0.062481867 | AB33: =Settings!$B$24*(T33-L$6)^2 -> 0.18396326 | AC33: =Settings!$B$25*(U33-M$6)^2 -> 0.64799689 | AD33: =SQRT(SUM(V33:AC33)) -> 1.3718268 | AE33: =AD33/Yardstick -> 0.5429939 | AF33: =EXP(-(AD33^2)/(2*Yardstick^2)) -> 0.86293044 | AG33: =AF33/$E$7 -> 0.0037256158 | AH33: -0.7265329 | AI33: 0 | AJ33: -1.0814918 | AK33: 0 | AL33: -1.1200769 | AM33: 0 | AN33: 0.89403445 | AO33: 1 | AP33: -0.37673917 | AQ33: 1
A34: 24 | B34: Drake Batherson | C34: 2023-24 & 2024-25 | D34: 26 | E34: 1 | F34: 0.069513607 | G34: -0.082440585 | H34: 0.31660199 | I34: 0.00010592703 | J34: 0.53133789 | K34: 17.516057 | L34: 2.4717436 | M34: 0.16657961 | N34: =(F34-Settings!$D$18)/Settings!$E$18 -> -0.4395252 | O34: =(G34-Settings!$D$19)/Settings!$E$19 -> -0.315787 | P34: =(H34-Settings!$D$20)/Settings!$E$20 -> 2.3871323 | Q34: =(I34-Settings!$D$21)/Settings!$E$21 -> 0.037511742 | R34: =(J34-Settings!$D$22)/Settings!$E$22 -> 0.76270729 | S34: =(K34-Settings!$D$23)/Settings!$E$23 -> 0.78513957 | T34: =(L34-Settings!$D$24)/Settings!$E$24 -> 0.8043744 | U34: =(M34-Settings!$D$25)/Settings!$E$25 -> 0.1483134 | V34: =Settings!$B$18*(N34-F$6)^2 -> 0.047290735 | W34: =Settings!$B$19*(O34-G$6)^2 -> 0.13442449 | X34: =Settings!$B$20*(P34-H$6)^2 -> 0.0031549873 | Y34: =Settings!$B$21*(Q34-I$6)^2 -> 0.16100978 | Z34: =Settings!$B$22*(R34-J$6)^2 -> 0.074381106 | AA34: =Settings!$B$23*(S34-K$6)^2 -> 0.88868679 | AB34: =Settings!$B$24*(T34-L$6)^2 -> 0.52105506 | AC34: =Settings!$B$25*(U34-M$6)^2 -> 0.10906394 | AD34: =SQRT(SUM(V34:AC34)) -> 1.3925038 | AE34: =AD34/Yardstick -> 0.55117826 | AF34: =EXP(-(AD34^2)/(2*Yardstick^2)) -> 0.85907527 | AG34: =AF34/$E$7 -> 0.0037089715 | AH34: 0.65328014 | AI34: 1
A35: 25 | B35: Sam Reinhart | C35: 2020-21 & 2021-22 | D35: 26 | E35: 1 | F35: 0.16623875 | G35: 0.11162263 | H35: 0.091111768 | I35: -0.010959551 | J35: 0.6200673 | K35: 17.855682 | L35: 4.1032811 | M35: -0.81740332 | N35: =(F35-Settings!$D$18)/Settings!$E$18 -> -0.093351934 | O35: =(G35-Settings!$D$19)/Settings!$E$19 -> 0.49270509 | P35: =(H35-Settings!$D$20)/Settings!$E$20 -> 0.34414753 | Q35: =(I35-Settings!$D$21)/Settings!$E$21 -> -0.098563844 | R35: =(J35-Settings!$D$22)/Settings!$E$22 -> 1.001438 | S35: =(K35-Settings!$D$23)/Settings!$E$23 -> 0.90308349 | T35: =(L35-Settings!$D$24)/Settings!$E$24 -> 1.9323455 | U35: =(M35-Settings!$D$25)/Settings!$E$25 -> -0.51529564 | V35: =Settings!$B$18*(N35-F$6)^2 -> 0.0039251401 | W35: =Settings!$B$19*(O35-G$6)^2 -> 2.5713071e-05 | X35: =Settings!$B$20*(P35-H$6)^2 -> 0.7352742 | Y35: =Settings!$B$21*(Q35-I$6)^2 -> 0.11587582 | Z35: =Settings!$B$22*(R35-J$6)^2 -> 0.14401463 | AA35: =Settings!$B$23*(S35-K$6)^2 -> 0.68022566 | AB35: =Settings!$B$24*(T35-L$6)^2 -> 0.16494128 | AC35: =Settings!$B$25*(U35-M$6)^2 -> 0.11112939 | AD35: =SQRT(SUM(V35:AC35)) -> 1.3983604 | AE35: =AD35/Yardstick -> 0.5534964 | AF35: =EXP(-(AD35^2)/(2*Yardstick^2)) -> 0.85797602 | AG35: =AF35/$E$7 -> 0.0037042255 | AH35: -1.0736689 | AI35: 1 | AJ35: 1.5612159 | AK35: 1 | AL35: 0.95568301 | AM35: 1 | AN35: -2.7501519 | AO35: 1
A36: 26 | B36: Logan Couture | C36: 2014-15 & 2015-16 | D36: 26 | E36: 0 | F36: 0.36999268 | G36: -0.0013826467 | H36: 0.34769374 | I36: 0.018077729 | J36: 0.2628532 | K36: 17.773507 | L36: 2.8649759 | M36: 0.92267762 | N36: =(F36-Settings!$D$18)/Settings!$E$18 -> 0.63587067 | O36: =(G36-Settings!$D$19)/Settings!$E$19 -> 0.021910704 | P36: =(H36-Settings!$D$20)/Settings!$E$20 -> 2.6688295 | Q36: =(I36-Settings!$D$21)/Settings!$E$21 -> 0.25851652 | R36: =(J36-Settings!$D$22)/Settings!$E$22 -> 0.040336608 | S36: =(K36-Settings!$D$23)/Settings!$E$23 -> 0.87454623 | T36: =(L36-Settings!$D$24)/Settings!$E$24 -> 1.0762374 | U36: =(M36-Settings!$D$25)/Settings!$E$25 -> 0.65823432 | V36: =Settings!$B$18*(N36-F$6)^2 -> 0.069415032 | W36: =Settings!$B$19*(O36-G$6)^2 -> 0.046490456 | X36: =Settings!$B$20*(P36-H$6)^2 -> 0.033177927 | Y36: =Settings!$B$21*(Q36-I$6)^2 -> 0.25009659 | Z36: =Settings!$B$22*(R36-J$6)^2 -> 0.0025326049 | AA36: =Settings!$B$23*(S36-K$6)^2 -> 0.7281127 | AB36: =Settings!$B$24*(T36-L$6)^2 -> 0.20248061 | AC36: =Settings!$B$25*(U36-M$6)^2 -> 0.70588431 | AD36: =SQRT(SUM(V36:AC36)) -> 1.427652 | AE36: =AD36/Yardstick -> 0.56509054 | AF36: =EXP(-(AD36^2)/(2*Yardstick^2)) -> 0.85243045 | AG36: =AF36/$E$7 -> 0.0036802831 | AH36: 0.49064431 | AI36: 0 | AJ36: 0.24529317 | AK36: 0 | AL36: -0.88786357 | AM36: 1 | AN36: -0.89879346 | AO36: 1 | AP36: 0.16323974 | AQ36: 1
